<mujoco model="g1">
    <compiler angle="radian" meshdir="../meshes/" />

    <statistic meansize="0.144785" extent="1.23314" center="0.025392 2.0634e-05 -0.245975"/>
    <default>
        <joint damping="0.001" armature="0.01" frictionloss="0.1"/>
    </default>
    
    <size njmax="500" nconmax="100" />
    <asset>
        <mesh name="pelvis" file="pelvis.STL" />
        <mesh name="pelvis_contour_link" file="pelvis_contour_link.STL" />
        <mesh name="left_hip_pitch_link" file="left_hip_pitch_link.STL" />
        <mesh name="left_hip_roll_link" file="left_hip_roll_link.STL" />
        <mesh name="left_hip_yaw_link" file="left_hip_yaw_link.STL" />
        <mesh name="left_knee_link" file="left_knee_link.STL" />
        <mesh name="left_ankle_pitch_link" file="left_ankle_pitch_link.STL" />
        <mesh name="left_ankle_roll_link" file="left_ankle_roll_link.STL" />
        <mesh name="right_hip_pitch_link" file="right_hip_pitch_link.STL" />
        <mesh name="right_hip_roll_link" file="right_hip_roll_link.STL" />
        <mesh name="right_hip_yaw_link" file="right_hip_yaw_link.STL" />
        <mesh name="right_knee_link" file="right_knee_link.STL" />
        <mesh name="right_ankle_pitch_link" file="right_ankle_pitch_link.STL" />
        <mesh name="right_ankle_roll_link" file="right_ankle_roll_link.STL" />
        <mesh name="waist_yaw_link" file="waist_yaw_link.STL" />
        <mesh name="waist_roll_link" file="waist_roll_link.STL" />
        <mesh name="torso_link" file="torso_link.STL" />
        <mesh name="logo_link" file="logo_link.STL" />
        <mesh name="head_link" file="head_link.STL" />
        <mesh name="waist_support_link" file="waist_support_link.STL" />
        <mesh name="left_shoulder_pitch_link" file="left_shoulder_pitch_link.STL" />
        <mesh name="left_shoulder_roll_link" file="left_shoulder_roll_link.STL" />
        <mesh name="left_shoulder_yaw_link" file="left_shoulder_yaw_link.STL" />
        <mesh name="left_elbow_link" file="left_elbow_link.STL" />
        <mesh name="left_wrist_roll_link" file="left_wrist_roll_link.STL" />
        <mesh name="left_wrist_pitch_link" file="left_wrist_pitch_link.STL" />
        <mesh name="left_wrist_yaw_link" file="left_wrist_yaw_link.STL" />
        <mesh name="left_rubber_hand" file="left_rubber_hand.STL" />
        <mesh name="right_shoulder_pitch_link" file="right_shoulder_pitch_link.STL" />
        <mesh name="right_shoulder_roll_link" file="right_shoulder_roll_link.STL" />
        <mesh name="right_shoulder_yaw_link" file="right_shoulder_yaw_link.STL" />
        <mesh name="right_elbow_link" file="right_elbow_link.STL" />
        <mesh name="right_wrist_roll_link" file="right_wrist_roll_link.STL" />
        <mesh name="right_wrist_pitch_link" file="right_wrist_pitch_link.STL" />
        <mesh name="right_wrist_yaw_link" file="right_wrist_yaw_link.STL" />
        <mesh name="right_rubber_hand" file="right_rubber_hand.STL" />
    </asset>
    <worldbody>
        <!--added by zsy-->
        <body name="pelvis" pos="0 0 0.793">
            <inertial pos="0 0 -0.07605" quat="1 0 -0.000399148 0" mass="3.813" diaginertia="0.010549 0.0093089 0.0079184"/>
            <light name="spotlight" mode="trackcom" pos="0 -2 10" dir="0 0 -1"/>
            <joint name="floating_base_joint" type="free" /> <!-- can fall free ps:zsy-->
            <geom type="mesh" contype="0" conaffinity="0" group="1" rgba="0.2 0.2 0.2 1" mesh="pelvis" />
            <geom type="mesh" contype="0" conaffinity="0" group="1" rgba="0.7 0.7 0.7 1" mesh="pelvis_contour_link" />
            <geom type="mesh" rgba="0.7 0.7 0.7 1" mesh="pelvis_contour_link" />
            <!--site name="imu_in_pelvis" size="0.01" pos="0.04525 0 -0.08339"/-->
            <body name="left_hip_pitch_link" pos="0 0.064452 -0.1027">
                <inertial pos="0.002741 0.047791 -0.02606" quat="0.954862 0.293964 0.0302556 0.030122" mass="1.35" diaginertia="0.00181517 0.00153422 0.00116212" />
                <joint name="left_hip_pitch_joint" pos="0 0 0" axis="0 1 0" limited="true" range="-2.5307 2.8798" />
                <geom type="mesh" contype="0" conaffinity="0" group="1" rgba="0.2 0.2 0.2 1" mesh="left_hip_pitch_link" />
                <geom type="mesh" rgba="0.2 0.2 0.2 1" mesh="left_hip_pitch_link" />
                <body name="left_hip_roll_link" pos="0 0.052 -0.030465" quat="0.996179 0 -0.0873386 0">
                    <inertial pos="0.029812 -0.001045 -0.087934" quat="0.977808 -1.97119e-05 0.205576 -0.0403793" mass="1.52" diaginertia="0.00254986 0.00241169 0.00148755" />
                    <joint name="left_hip_roll_joint" pos="0 0 0" axis="1 0 0" limited="true" range="-0.5236 2.9671" />
                    <geom type="mesh" contype="0" conaffinity="0" group="1" rgba="0.7 0.7 0.7 1" mesh="left_hip_roll_link" />
                    <geom type="mesh" rgba="0.7 0.7 0.7 1" mesh="left_hip_roll_link" />
                    <body name="left_hip_yaw_link" pos="0.025001 0 -0.12412">
                        <inertial pos="-0.057709 -0.010981 -0.15078" quat="0.600598 0.15832 0.223482 0.751181" mass="1.702" diaginertia="0.00776166 0.00717575 0.00160139" />
                        <joint name="left_hip_yaw_joint" pos="0 0 0" axis="0 0 1" limited="true" range="-2.7576 2.7576" />
                        <geom type="mesh" contype="0" conaffinity="0" group="1" rgba="0.7 0.7 0.7 1" mesh="left_hip_yaw_link" />
                        <geom type="mesh" rgba="0.7 0.7 0.7 1" mesh="left_hip_yaw_link" />
                        <body name="left_knee_link" pos="-0.078273 0.0021489 -0.17734" quat="0.996179 0 0.0873386 0">
                            <inertial pos="0.005457 0.003964 -0.12074" quat="0.923418 -0.0327699 0.0158246 0.382067" mass="1.932" diaginertia="0.0113804 0.0112778 0.00146458" />
                            <joint name="left_knee_joint" pos="0 0 0" axis="0 1 0" limited="true" range="-0.087267 2.8798" />
                            <geom type="mesh" contype="0" conaffinity="0" group="1" rgba="0.7 0.7 0.7 1" mesh="left_knee_link" />
                            <geom type="mesh" rgba="0.7 0.7 0.7 1" mesh="left_knee_link" />
                            <body name="left_ankle_pitch_link" pos="0 -9.4445e-05 -0.30001">
                                <inertial pos="0.0228404 0 -0.0290873" quat="0.466405 0.531473 0.532001 0.46581" mass="0.682" diaginertia="0.00184456 0.00177922 0.000341134" />
                                <joint name="left_ankle_pitch_joint" pos="0 0 0" axis="0 1 0" limited="true" range="-0.87267 0.5236" />
                                <geom type="mesh" contype="0" conaffinity="0" group="1" rgba="0.7 0.7 0.7 1" mesh="left_ankle_pitch_link" />
                                <geom type="mesh" rgba="0.7 0.7 0.7 1" mesh="left_ankle_pitch_link" />
                                <geom pos="0 0 -0.017558" type="mesh" contype="0" conaffinity="0" group="1" rgba="0.2 0.2 0.2 1" mesh="left_ankle_roll_link" />
                                <geom size="0.005" pos="-0.05 0.025 -0.047558" rgba="0.2 0.2 0.2 1" />
                                <geom size="0.005" pos="-0.05 -0.025 -0.047558" rgba="0.2 0.2 0.2 1" />
                                <geom size="0.005" pos="0.12 0.03 -0.047558" rgba="0.2 0.2 0.2 1" />
                                <geom size="0.005" pos="0.12 -0.03 -0.047558" rgba="0.2 0.2 0.2 1" />
                            </body>
                        </body>
                    </body>
                </body>
            </body>

            <body name="right_hip_pitch_link" pos="0 -0.064452 -0.1027">
                <inertial pos="0.002741 -0.047791 -0.02606" quat="0.954862 -0.293964 0.0302556 -0.030122" mass="1.35" diaginertia="0.00181517 0.00153422 0.00116212" />
                <joint name="right_hip_pitch_joint" pos="0 0 0" axis="0 1 0" limited="true" range="-2.5307 2.8798" />
                <geom type="mesh" contype="0" conaffinity="0" group="1" rgba="0.2 0.2 0.2 1" mesh="right_hip_pitch_link" />
                <geom type="mesh" rgba="0.2 0.2 0.2 1" mesh="right_hip_pitch_link" />
                <body name="right_hip_roll_link" pos="0 -0.052 -0.030465" quat="0.996179 0 -0.0873386 0">
                    <inertial pos="0.029812 0.001045 -0.087934" quat="0.977808 1.97119e-05 0.205576 0.0403793" mass="1.52" diaginertia="0.00254986 0.00241169 0.00148755" />
                    <joint name="right_hip_roll_joint" pos="0 0 0" axis="1 0 0" limited="true" range="-2.9671 0.5236" />
                    <geom type="mesh" contype="0" conaffinity="0" group="1" rgba="0.7 0.7 0.7 1" mesh="right_hip_roll_link" />
                    <geom type="mesh" rgba="0.7 0.7 0.7 1" mesh="right_hip_roll_link" />
                    <body name="right_hip_yaw_link" pos="0.025001 0 -0.12412">
                        <inertial pos="-0.057709 0.010981 -0.15078" quat="0.751181 0.223482 0.15832 0.600598" mass="1.702" diaginertia="0.00776166 0.00717575 0.00160139" />
                        <joint name="right_hip_yaw_joint" pos="0 0 0" axis="0 0 1" limited="true" range="-2.7576 2.7576" />
                        <geom type="mesh" contype="0" conaffinity="0" group="1" rgba="0.7 0.7 0.7 1" mesh="right_hip_yaw_link" />
                        <geom type="mesh" rgba="0.7 0.7 0.7 1" mesh="right_hip_yaw_link" />
                        <body name="right_knee_link" pos="-0.078273 -0.0021489 -0.17734" quat="0.996179 0 0.0873386 0">
                            <inertial pos="0.005457 -0.003964 -0.12074" quat="0.923439 0.0345276 0.0116333 -0.382012" mass="1.932" diaginertia="0.011374 0.0112843 0.00146452" />
                            <joint name="right_knee_joint" pos="0 0 0" axis="0 1 0" limited="true" range="-0.087267 2.8798" />
                            <geom type="mesh" contype="0" conaffinity="0" group="1" rgba="0.7 0.7 0.7 1" mesh="right_knee_link" />
                            <geom type="mesh" rgba="0.7 0.7 0.7 1" mesh="right_knee_link" />
                            <body name="right_ankle_pitch_link" pos="0 9.4445e-05 -0.30001">
                                <inertial pos="0.0228404 0 -0.0290873" quat="0.46581 0.532001 0.531473 0.466405" mass="0.682" diaginertia="0.00184456 0.00177922 0.000341134" />
                                <joint name="right_ankle_pitch_joint" pos="0 0 0" axis="0 1 0" limited="true" range="-0.87267 0.5236" />
                                <geom type="mesh" contype="0" conaffinity="0" group="1" rgba="0.7 0.7 0.7 1" mesh="right_ankle_pitch_link" />
                                <geom type="mesh" rgba="0.7 0.7 0.7 1" mesh="right_ankle_pitch_link" />
                                <geom pos="0 0 -0.017558" type="mesh" contype="0" conaffinity="0" group="1" rgba="0.2 0.2 0.2 1" mesh="right_ankle_roll_link" />
                                <geom size="0.005" pos="-0.05 0.025 -0.047558" rgba="0.2 0.2 0.2 1" />
                                <geom size="0.005" pos="-0.05 -0.025 -0.047558" rgba="0.2 0.2 0.2 1" />
                                <geom size="0.005" pos="0.12 0.03 -0.047558" rgba="0.2 0.2 0.2 1" />
                                <geom size="0.005" pos="0.12 -0.03 -0.047558" rgba="0.2 0.2 0.2 1" />
                            </body>
                        </body>
                    </body>
                </body>
            </body>
            <body name="waist_yaw_link" pos="0 0 0">
                <inertial pos="-0.0005488 0.000252665 0.227606" quat="0.999882 0.000232906 0.0148792 -0.00381789" mass="9.891" diaginertia="0.136836 0.124773 0.0327301" />
                <joint name="waist_yaw_joint" pos="0 0 0" axis="0 0 1" limited="true" range="-2.618 2.618" />
                <geom type="mesh" contype="0" conaffinity="0" group="1" rgba="0.7 0.7 0.7 1" mesh="waist_yaw_link" />
                <geom pos="-0.0039635 0 0.035" type="mesh" contype="0" conaffinity="0" group="1" rgba="0.7 0.7 0.7 1" mesh="waist_roll_link" />
                <geom pos="-0.0039635 0 0.054" type="mesh" contype="0" conaffinity="0" group="1" rgba="0.7 0.7 0.7 1" mesh="torso_link" />
                <geom pos="-0.0039635 0 0.054" type="mesh" rgba="0.7 0.7 0.7 1" mesh="torso_link" />
                <geom type="mesh" contype="0" conaffinity="0" group="1" rgba="0.2 0.2 0.2 1" mesh="logo_link" />
                <geom type="mesh" rgba="0.2 0.2 0.2 1" mesh="logo_link" />
                <geom type="mesh" contype="0" conaffinity="0" group="1" rgba="0.2 0.2 0.2 1" mesh="head_link" />
                <geom type="mesh" rgba="0.2 0.2 0.2 1" mesh="head_link" />
                <geom type="mesh" contype="0" conaffinity="0" group="1" rgba="0.7 0.7 0.7 1" mesh="waist_support_link" />
                <geom type="mesh" rgba="0.7 0.7 0.7 1" mesh="waist_support_link" />
                <body name="left_shoulder_pitch_link" pos="-7.2e-06 0.10022 0.29178" quat="0.990264 0.139201 1.38722e-05 -9.86868e-05">
                    <inertial pos="0 0.035892 -0.011628" quat="0.654152 0.0130458 -0.326267 0.68225" mass="0.718" diaginertia="0.000465864 0.000432842 0.000406394" />
                    <joint name="left_shoulder_pitch_joint" pos="0 0 0" axis="0 1 0" limited="true" range="-3.0892 2.6704" />
                    <geom type="mesh" contype="0" conaffinity="0" group="1" rgba="0.7 0.7 0.7 1" mesh="left_shoulder_pitch_link" />
                    <geom size="0.03 0.025" pos="0 0.04 -0.01" quat="0.707107 0 0.707107 0" type="cylinder" rgba="0.7 0.7 0.7 1" />
                    <body name="left_shoulder_roll_link" pos="0 0.038 -0.013831" quat="0.990268 -0.139172 0 0">
                        <inertial pos="-0.000227 0.00727 -0.063243" quat="0.701256 -0.0196223 -0.00710317 0.712604" mass="0.643" diaginertia="0.000691311 0.000618011 0.000388977" />
                        <joint name="left_shoulder_roll_joint" pos="0 0 0" axis="1 0 0" limited="true" range="-1.5882 2.2515" />
                        <geom type="mesh" contype="0" conaffinity="0" group="1" rgba="0.7 0.7 0.7 1" mesh="left_shoulder_roll_link" />
                        <geom size="0.03 0.015" pos="-0.004 0.006 -0.053" type="cylinder" rgba="0.7 0.7 0.7 1" />
                        <body name="left_shoulder_yaw_link" pos="0 0.00624 -0.1032">
                            <inertial pos="0.010773 -0.002949 -0.072009" quat="0.716879 -0.0964829 -0.0679942 0.687134" mass="0.734" diaginertia="0.00106187 0.00103217 0.000400661" />
                            <joint name="left_shoulder_yaw_joint" pos="0 0 0" axis="0 0 1" limited="true" range="-2.618 2.618" />
                            <geom type="mesh" contype="0" conaffinity="0" group="1" rgba="0.7 0.7 0.7 1" mesh="left_shoulder_yaw_link" />
                            <geom type="mesh" rgba="0.7 0.7 0.7 1" mesh="left_shoulder_yaw_link" />
                            <body name="left_elbow_link" pos="0.015783 0 -0.080518">
                                <inertial pos="0.134675 0.00265598 -0.0101165" quat="0.514554 0.498203 0.50107 0.485754" mass="1.42407" diaginertia="0.00848486 0.00842107 0.000653284" />
                                <joint name="left_elbow_joint" pos="0 0 0" axis="0 1 0" limited="true" range="-1.0472 2.0944" />
                                <geom type="mesh" contype="0" conaffinity="0" group="1" rgba="0.7 0.7 0.7 1" mesh="left_elbow_link" />
                                <geom type="mesh" rgba="0.7 0.7 0.7 1" mesh="left_elbow_link" />
                                <geom pos="0.1 0.00188791 -0.01" type="mesh" contype="0" conaffinity="0" group="1" rgba="0.7 0.7 0.7 1" mesh="left_wrist_roll_link" />
                                <geom pos="0.1 0.00188791 -0.01" type="mesh" rgba="0.7 0.7 0.7 1" mesh="left_wrist_roll_link" />
                                <geom pos="0.138 0.00188791 -0.01" type="mesh" contype="0" conaffinity="0" group="1" rgba="0.7 0.7 0.7 1" mesh="left_wrist_pitch_link" />
                                <geom pos="0.138 0.00188791 -0.01" type="mesh" rgba="0.7 0.7 0.7 1" mesh="left_wrist_pitch_link" />
                                <geom pos="0.184 0.00188791 -0.01" type="mesh" contype="0" conaffinity="0" group="1" rgba="0.7 0.7 0.7 1" mesh="left_wrist_yaw_link" />
                                <geom pos="0.184 0.00188791 -0.01" type="mesh" rgba="0.7 0.7 0.7 1" mesh="left_wrist_yaw_link" />
                                <geom pos="0.2255 0.00488791 -0.01" type="mesh" contype="0" conaffinity="0" group="1" rgba="0.7 0.7 0.7 1" mesh="left_rubber_hand" />
                            </body>
                        </body>
                    </body>
                </body>
                <body name="right_shoulder_pitch_link" pos="-7.2e-06 -0.10021 0.29178" quat="0.990264 -0.139201 1.38722e-05 9.86868e-05">
                    <inertial pos="0 -0.035892 -0.011628" quat="0.68225 -0.326267 0.0130458 0.654152" mass="0.718" diaginertia="0.000465864 0.000432842 0.000406394" />
                    <joint name="right_shoulder_pitch_joint" pos="0 0 0" axis="0 1 0" limited="true" range="-3.0892 2.6704" />
                    <geom type="mesh" contype="0" conaffinity="0" group="1" rgba="0.7 0.7 0.7 1" mesh="right_shoulder_pitch_link" />
                    <geom size="0.03 0.025" pos="0 -0.04 -0.01" quat="0.707107 0 0.707107 0" type="cylinder" rgba="0.7 0.7 0.7 1" />
                    <body name="right_shoulder_roll_link" pos="0 -0.038 -0.013831" quat="0.990268 0.139172 0 0">
                        <inertial pos="-0.000227 -0.00727 -0.063243" quat="0.712604 -0.00710317 -0.0196223 0.701256" mass="0.643" diaginertia="0.000691311 0.000618011 0.000388977" />
                        <joint name="right_shoulder_roll_joint" pos="0 0 0" axis="1 0 0" limited="true" range="-2.2515 1.5882" />
                        <geom type="mesh" contype="0" conaffinity="0" group="1" rgba="0.7 0.7 0.7 1" mesh="right_shoulder_roll_link" />
                        <geom size="0.03 0.015" pos="-0.004 -0.006 -0.053" type="cylinder" rgba="0.7 0.7 0.7 1" />
                        <body name="right_shoulder_yaw_link" pos="0 -0.00624 -0.1032">
                            <inertial pos="0.010773 0.002949 -0.072009" quat="0.687134 -0.0679942 -0.0964829 0.716879" mass="0.734" diaginertia="0.00106187 0.00103217 0.000400661" />
                            <joint name="right_shoulder_yaw_joint" pos="0 0 0" axis="0 0 1" limited="true" range="-2.618 2.618" />
                            <geom type="mesh" contype="0" conaffinity="0" group="1" rgba="0.7 0.7 0.7 1" mesh="right_shoulder_yaw_link" />
                            <geom type="mesh" rgba="0.7 0.7 0.7 1" mesh="right_shoulder_yaw_link" />
                            <body name="right_elbow_link" pos="0.015783 0 -0.080518">
                                <inertial pos="0.134675 -0.00265598 -0.0101165" quat="0.485754 0.50107 0.498203 0.514554" mass="1.42407" diaginertia="0.00848486 0.00842107 0.000653284" />
                                <joint name="right_elbow_joint" pos="0 0 0" axis="0 1 0" limited="true" range="-1.0472 2.0944" />
                                <geom type="mesh" contype="0" conaffinity="0" group="1" rgba="0.7 0.7 0.7 1" mesh="right_elbow_link" />
                                <geom type="mesh" rgba="0.7 0.7 0.7 1" mesh="right_elbow_link" />
                                <geom pos="0.1 -0.00188791 -0.01" type="mesh" contype="0" conaffinity="0" group="1" rgba="0.7 0.7 0.7 1" mesh="right_wrist_roll_link" />
                                <geom pos="0.1 -0.00188791 -0.01" type="mesh" rgba="0.7 0.7 0.7 1" mesh="right_wrist_roll_link" />
                                <geom pos="0.138 -0.00188791 -0.01" type="mesh" contype="0" conaffinity="0" group="1" rgba="0.7 0.7 0.7 1" mesh="right_wrist_pitch_link" />
                                <geom pos="0.138 -0.00188791 -0.01" type="mesh" rgba="0.7 0.7 0.7 1" mesh="right_wrist_pitch_link" />
                                <geom pos="0.184 -0.00188791 -0.01" type="mesh" contype="0" conaffinity="0" group="1" rgba="0.7 0.7 0.7 1" mesh="right_wrist_yaw_link" />
                                <geom pos="0.184 -0.00188791 -0.01" type="mesh" rgba="0.7 0.7 0.7 1" mesh="right_wrist_yaw_link" />
                                <geom pos="0.2255 -0.00488791 -0.01" type="mesh" contype="0" conaffinity="0" group="1" rgba="0.7 0.7 0.7 1" mesh="right_rubber_hand" />
                            </body>
                        </body>
                    </body>
                </body>
            </body>
        </body> 
    </worldbody>

    <actuator>
        <motor name="left_hip_yaw_joint" joint="left_hip_yaw_joint" ctrllimited="true" ctrlrange="-88 88"/> 
        <motor name="left_hip_roll_joint" joint="left_hip_roll_joint" ctrllimited="true" ctrlrange="-88 88"/>
        <motor name="left_hip_pitch_joint" joint="left_hip_pitch_joint" ctrllimited="true" ctrlrange="-88 88"/>
        <motor name="left_knee_joint" joint="left_knee_joint" ctrllimited="true" ctrlrange="-139 139"/>
        <motor name="left_ankle_pitch_joint" joint="left_ankle_pitch_joint" ctrllimited="true" ctrlrange="-40 40"/>
        <motor name="right_hip_yaw_joint" joint="right_hip_yaw_joint" ctrllimited="true" ctrlrange="-88 88"/>
        <motor name="right_hip_roll_joint" joint="right_hip_roll_joint" ctrllimited="true" ctrlrange="-88 88"/>
        <motor name="right_hip_pitch_joint" joint="right_hip_pitch_joint" ctrllimited="true" ctrlrange="-88 88"/>
        <motor name="right_knee_joint" joint="right_knee_joint" ctrllimited="true" ctrlrange="-139 139"/>
        <motor name="right_ankle_pitch_joint" joint="right_ankle_pitch_joint" ctrllimited="true" ctrlrange="-40 40"/>
        <motor name="waist_yaw_joint" joint="waist_yaw_joint" ctrllimited="true" ctrlrange="-40 40"/>
        <motor name="left_shoulder_pitch_joint" joint="left_shoulder_pitch_joint" ctrllimited="true" ctrlrange="-20 20"/>
        <motor name="left_shoulder_roll_joint" joint="left_shoulder_roll_joint" ctrllimited="true" ctrlrange="-20 20"/>
        <motor name="left_shoulder_yaw_joint" joint="left_shoulder_yaw_joint" ctrllimited="true" ctrlrange="-20 20"/>
        <motor name="left_elbow_joint" joint="left_elbow_joint" ctrllimited="true" ctrlrange="-20 20"/>
        <motor name="right_shoulder_pitch_joint" joint="right_shoulder_pitch_joint" ctrllimited="true" ctrlrange="-20 20"/>
        <motor name="right_shoulder_roll_joint" joint="right_shoulder_roll_joint" ctrllimited="true" ctrlrange="-20 20"/>
        <motor name="right_shoulder_yaw_joint" joint="right_shoulder_yaw_joint" ctrllimited="true" ctrlrange="-20 20"/>
        <motor name="right_elbow_joint" joint="right_elbow_joint" ctrllimited="true" ctrlrange="-20 20"/>
    </actuator>
</mujoco>




